Traceback (most recent call last):
  File "/usr/local/lib/python3.10/dist-packages/jupyter_cache/executors/utils.py", line 58, in single_nb_execution
    executenb(
  File "/usr/local/lib/python3.10/dist-packages/nbclient/client.py", line 1305, in execute
    return NotebookClient(nb=nb, resources=resources, km=km, **kwargs).execute()
  File "/usr/local/lib/python3.10/dist-packages/jupyter_core/utils/__init__.py", line 173, in wrapped
    return loop.run_until_complete(inner)
  File "/usr/lib/python3.10/asyncio/base_events.py", line 649, in run_until_complete
    return future.result()
  File "/usr/local/lib/python3.10/dist-packages/nbclient/client.py", line 705, in async_execute
    await self.async_execute_cell(
  File "/usr/local/lib/python3.10/dist-packages/nbclient/client.py", line 1058, in async_execute_cell
    await self._check_raise_for_error(cell, cell_index, exec_reply)
  File "/usr/local/lib/python3.10/dist-packages/nbclient/client.py", line 914, in _check_raise_for_error
    raise CellExecutionError.from_cell_and_msg(cell, exec_reply_content)
nbclient.exceptions.CellExecutionError: An error occurred while executing the following cell:
------------------
import matplotlib.pyplot as plt
import matplotlib.image as mpimg

# Baca gambar menggunakan matplotlib
img = mpimg.imread('Screenshot 2023-11-29 191621.png')  # Ganti 'nama_gambar.png' dengan nama gambar yang sesuai

# Tampilkan gambar
plt.imshow(img)
plt.axis('off')  # Menghilangkan sumbu
plt.show()

------------------


[0;31m---------------------------------------------------------------------------[0m
[0;31mFileNotFoundError[0m                         Traceback (most recent call last)
[0;32m<ipython-input-1-d6acb40c4bc8>[0m in [0;36m<cell line: 5>[0;34m()[0m
[1;32m      3[0m [0;34m[0m[0m
[1;32m      4[0m [0;31m# Baca gambar menggunakan matplotlib[0m[0;34m[0m[0;34m[0m[0m
[0;32m----> 5[0;31m [0mimg[0m [0;34m=[0m [0mmpimg[0m[0;34m.[0m[0mimread[0m[0;34m([0m[0;34m'Screenshot 2023-11-29 191621.png'[0m[0;34m)[0m  [0;31m# Ganti 'nama_gambar.png' dengan nama gambar yang sesuai[0m[0;34m[0m[0;34m[0m[0m
[0m[1;32m      6[0m [0;34m[0m[0m
[1;32m      7[0m [0;31m# Tampilkan gambar[0m[0;34m[0m[0;34m[0m[0m

[0;32m/usr/local/lib/python3.10/dist-packages/matplotlib/image.py[0m in [0;36mimread[0;34m(fname, format)[0m
[1;32m   1561[0m             [0;34m"``np.array(PIL.Image.open(urllib.request.urlopen(url)))``."[0m[0;34m[0m[0;34m[0m[0m
[1;32m   1562[0m             )
[0;32m-> 1563[0;31m     [0;32mwith[0m [0mimg_open[0m[0;34m([0m[0mfname[0m[0;34m)[0m [0;32mas[0m [0mimage[0m[0;34m:[0m[0;34m[0m[0;34m[0m[0m
[0m[1;32m   1564[0m         return (_pil_png_to_float_array(image)
[1;32m   1565[0m                 [0;32mif[0m [0misinstance[0m[0;34m([0m[0mimage[0m[0;34m,[0m [0mPIL[0m[0;34m.[0m[0mPngImagePlugin[0m[0;34m.[0m[0mPngImageFile[0m[0;34m)[0m [0;32melse[0m[0;34m[0m[0;34m[0m[0m

[0;32m/usr/local/lib/python3.10/dist-packages/PIL/ImageFile.py[0m in [0;36m__init__[0;34m(self, fp, filename)[0m
[1;32m    103[0m         [0;32mif[0m [0mis_path[0m[0;34m([0m[0mfp[0m[0;34m)[0m[0;34m:[0m[0;34m[0m[0;34m[0m[0m
[1;32m    104[0m             [0;31m# filename[0m[0;34m[0m[0;34m[0m[0m
[0;32m--> 105[0;31m             [0mself[0m[0;34m.[0m[0mfp[0m [0;34m=[0m [0mopen[0m[0;34m([0m[0mfp[0m[0;34m,[0m [0;34m"rb"[0m[0;34m)[0m[0;34m[0m[0;34m[0m[0m
[0m[1;32m    106[0m             [0mself[0m[0;34m.[0m[0mfilename[0m [0;34m=[0m [0mfp[0m[0;34m[0m[0;34m[0m[0m
[1;32m    107[0m             [0mself[0m[0;34m.[0m[0m_exclusive_fp[0m [0;34m=[0m [0;32mTrue[0m[0;34m[0m[0;34m[0m[0m

[0;31mFileNotFoundError[0m: [Errno 2] No such file or directory: 'Screenshot 2023-11-29 191621.png'

